[2025-09-06 12:51:53,098] {taskinstance.py:1159} INFO - Dependencies all met for <TaskInstance: dados_climatico.extrair_dados scheduled__2025-08-25T00:00:00+00:00 [queued]>
[2025-09-06 12:51:53,112] {taskinstance.py:1159} INFO - Dependencies all met for <TaskInstance: dados_climatico.extrair_dados scheduled__2025-08-25T00:00:00+00:00 [queued]>
[2025-09-06 12:51:53,113] {taskinstance.py:1356} INFO - 
--------------------------------------------------------------------------------
[2025-09-06 12:51:53,113] {taskinstance.py:1357} INFO - Starting attempt 1 of 1
[2025-09-06 12:51:53,113] {taskinstance.py:1358} INFO - 
--------------------------------------------------------------------------------
[2025-09-06 12:51:53,151] {taskinstance.py:1377} INFO - Executing <Task(PythonOperator): extrair_dados> on 2025-08-25 00:00:00+00:00
[2025-09-06 12:51:53,159] {standard_task_runner.py:52} INFO - Started process 35143 to run task
[2025-09-06 12:51:53,165] {standard_task_runner.py:79} INFO - Running: ['airflow', 'tasks', 'run', 'dados_climatico', 'extrair_dados', 'scheduled__2025-08-25T00:00:00+00:00', '--job-id', '30', '--raw', '--subdir', 'DAGS_FOLDER/dados_climaticos.py', '--cfg-path', '/tmp/tmpn2wubwg3', '--error-file', '/tmp/tmp_zo4rwu9']
[2025-09-06 12:51:53,166] {standard_task_runner.py:80} INFO - Job 30: Subtask extrair_dados
[2025-09-06 12:51:53,237] {task_command.py:370} INFO - Running <TaskInstance: dados_climatico.extrair_dados scheduled__2025-08-25T00:00:00+00:00 [running]> on host lucas-Lenovo-ideapad-320-14IKB
[2025-09-06 12:51:53,330] {taskinstance.py:1569} INFO - Exporting the following env vars:
AIRFLOW_CTX_DAG_OWNER=airflow
AIRFLOW_CTX_DAG_ID=dados_climatico
AIRFLOW_CTX_TASK_ID=extrair_dados
AIRFLOW_CTX_EXECUTION_DATE=2025-08-25T00:00:00+00:00
AIRFLOW_CTX_TRY_NUMBER=1
AIRFLOW_CTX_DAG_RUN_ID=scheduled__2025-08-25T00:00:00+00:00
[2025-09-06 12:51:53,331] {taskinstance.py:1889} ERROR - Task failed with exception
Traceback (most recent call last):
  File "/home/lucas/Documents/airflowalura/venv/lib/python3.9/site-packages/airflow/operators/python.py", line 171, in execute
    return_value = self.execute_callable()
  File "/home/lucas/Documents/airflowalura/venv/lib/python3.9/site-packages/airflow/operators/python.py", line 189, in execute_callable
    return self.python_callable(*self.op_args, **self.op_kwargs)
  File "/home/lucas/Documents/airflowalura/dags/dados_climaticos.py", line 26, in extrair_dados
    data_fim = data_inicio.add(days= 7)
AttributeError: 'str' object has no attribute 'add'
[2025-09-06 12:51:53,335] {taskinstance.py:1395} INFO - Marking task as FAILED. dag_id=dados_climatico, task_id=extrair_dados, execution_date=20250825T000000, start_date=20250906T155153, end_date=20250906T155153
[2025-09-06 12:51:53,364] {standard_task_runner.py:92} ERROR - Failed to execute job 30 for task extrair_dados ('str' object has no attribute 'add'; 35143)
[2025-09-06 12:51:53,377] {local_task_job.py:156} INFO - Task exited with return code 1
[2025-09-06 12:51:53,403] {local_task_job.py:273} INFO - 0 downstream tasks scheduled from follow-on schedule check
[2025-09-06 13:02:21,491] {taskinstance.py:1159} INFO - Dependencies all met for <TaskInstance: dados_climatico.extrair_dados scheduled__2025-08-25T00:00:00+00:00 [queued]>
[2025-09-06 13:02:21,499] {taskinstance.py:1159} INFO - Dependencies all met for <TaskInstance: dados_climatico.extrair_dados scheduled__2025-08-25T00:00:00+00:00 [queued]>
[2025-09-06 13:02:21,499] {taskinstance.py:1356} INFO - 
--------------------------------------------------------------------------------
[2025-09-06 13:02:21,500] {taskinstance.py:1357} INFO - Starting attempt 1 of 1
[2025-09-06 13:02:21,500] {taskinstance.py:1358} INFO - 
--------------------------------------------------------------------------------
[2025-09-06 13:02:21,530] {taskinstance.py:1377} INFO - Executing <Task(PythonOperator): extrair_dados> on 2025-08-25 00:00:00+00:00
[2025-09-06 13:02:21,537] {standard_task_runner.py:52} INFO - Started process 36696 to run task
[2025-09-06 13:02:21,544] {standard_task_runner.py:79} INFO - Running: ['airflow', 'tasks', 'run', 'dados_climatico', 'extrair_dados', 'scheduled__2025-08-25T00:00:00+00:00', '--job-id', '38', '--raw', '--subdir', 'DAGS_FOLDER/dados_climaticos.py', '--cfg-path', '/tmp/tmpeduxthx2', '--error-file', '/tmp/tmp8ojb2zu2']
[2025-09-06 13:02:21,545] {standard_task_runner.py:80} INFO - Job 38: Subtask extrair_dados
[2025-09-06 13:02:21,625] {task_command.py:370} INFO - Running <TaskInstance: dados_climatico.extrair_dados scheduled__2025-08-25T00:00:00+00:00 [running]> on host lucas-Lenovo-ideapad-320-14IKB
[2025-09-06 13:02:21,732] {taskinstance.py:1569} INFO - Exporting the following env vars:
AIRFLOW_CTX_DAG_OWNER=airflow
AIRFLOW_CTX_DAG_ID=dados_climatico
AIRFLOW_CTX_TASK_ID=extrair_dados
AIRFLOW_CTX_EXECUTION_DATE=2025-08-25T00:00:00+00:00
AIRFLOW_CTX_TRY_NUMBER=1
AIRFLOW_CTX_DAG_RUN_ID=scheduled__2025-08-25T00:00:00+00:00
[2025-09-06 13:02:22,757] {python.py:173} INFO - Done. Returned value was: None
[2025-09-06 13:02:22,783] {taskinstance.py:1395} INFO - Marking task as SUCCESS. dag_id=dados_climatico, task_id=extrair_dados, execution_date=20250825T000000, start_date=20250906T160221, end_date=20250906T160222
[2025-09-06 13:02:22,842] {local_task_job.py:156} INFO - Task exited with return code 0
[2025-09-06 13:02:22,873] {local_task_job.py:273} INFO - 0 downstream tasks scheduled from follow-on schedule check
