[2025-09-06 12:51:49,712] {taskinstance.py:1159} INFO - Dependencies all met for <TaskInstance: dados_climatico.extrair_dados scheduled__2025-08-18T00:00:00+00:00 [queued]>
[2025-09-06 12:51:49,720] {taskinstance.py:1159} INFO - Dependencies all met for <TaskInstance: dados_climatico.extrair_dados scheduled__2025-08-18T00:00:00+00:00 [queued]>
[2025-09-06 12:51:49,720] {taskinstance.py:1356} INFO - 
--------------------------------------------------------------------------------
[2025-09-06 12:51:49,721] {taskinstance.py:1357} INFO - Starting attempt 1 of 1
[2025-09-06 12:51:49,721] {taskinstance.py:1358} INFO - 
--------------------------------------------------------------------------------
[2025-09-06 12:51:49,760] {taskinstance.py:1377} INFO - Executing <Task(PythonOperator): extrair_dados> on 2025-08-18 00:00:00+00:00
[2025-09-06 12:51:49,767] {standard_task_runner.py:52} INFO - Started process 35130 to run task
[2025-09-06 12:51:49,774] {standard_task_runner.py:79} INFO - Running: ['airflow', 'tasks', 'run', 'dados_climatico', 'extrair_dados', 'scheduled__2025-08-18T00:00:00+00:00', '--job-id', '29', '--raw', '--subdir', 'DAGS_FOLDER/dados_climaticos.py', '--cfg-path', '/tmp/tmpawyyog0y', '--error-file', '/tmp/tmpola3_ang']
[2025-09-06 12:51:49,776] {standard_task_runner.py:80} INFO - Job 29: Subtask extrair_dados
[2025-09-06 12:51:49,857] {task_command.py:370} INFO - Running <TaskInstance: dados_climatico.extrair_dados scheduled__2025-08-18T00:00:00+00:00 [running]> on host lucas-Lenovo-ideapad-320-14IKB
[2025-09-06 12:51:49,970] {taskinstance.py:1569} INFO - Exporting the following env vars:
AIRFLOW_CTX_DAG_OWNER=airflow
AIRFLOW_CTX_DAG_ID=dados_climatico
AIRFLOW_CTX_TASK_ID=extrair_dados
AIRFLOW_CTX_EXECUTION_DATE=2025-08-18T00:00:00+00:00
AIRFLOW_CTX_TRY_NUMBER=1
AIRFLOW_CTX_DAG_RUN_ID=scheduled__2025-08-18T00:00:00+00:00
[2025-09-06 12:51:49,971] {taskinstance.py:1889} ERROR - Task failed with exception
Traceback (most recent call last):
  File "/home/lucas/Documents/airflowalura/venv/lib/python3.9/site-packages/airflow/operators/python.py", line 171, in execute
    return_value = self.execute_callable()
  File "/home/lucas/Documents/airflowalura/venv/lib/python3.9/site-packages/airflow/operators/python.py", line 189, in execute_callable
    return self.python_callable(*self.op_args, **self.op_kwargs)
  File "/home/lucas/Documents/airflowalura/dags/dados_climaticos.py", line 26, in extrair_dados
    data_fim = data_inicio.add(days= 7)
AttributeError: 'str' object has no attribute 'add'
[2025-09-06 12:51:49,979] {taskinstance.py:1395} INFO - Marking task as FAILED. dag_id=dados_climatico, task_id=extrair_dados, execution_date=20250818T000000, start_date=20250906T155149, end_date=20250906T155149
[2025-09-06 12:51:50,014] {standard_task_runner.py:92} ERROR - Failed to execute job 29 for task extrair_dados ('str' object has no attribute 'add'; 35130)
[2025-09-06 12:51:50,025] {local_task_job.py:156} INFO - Task exited with return code 1
[2025-09-06 12:51:50,054] {local_task_job.py:273} INFO - 0 downstream tasks scheduled from follow-on schedule check
[2025-09-06 13:02:17,215] {taskinstance.py:1159} INFO - Dependencies all met for <TaskInstance: dados_climatico.extrair_dados scheduled__2025-08-18T00:00:00+00:00 [queued]>
[2025-09-06 13:02:17,227] {taskinstance.py:1159} INFO - Dependencies all met for <TaskInstance: dados_climatico.extrair_dados scheduled__2025-08-18T00:00:00+00:00 [queued]>
[2025-09-06 13:02:17,228] {taskinstance.py:1356} INFO - 
--------------------------------------------------------------------------------
[2025-09-06 13:02:17,228] {taskinstance.py:1357} INFO - Starting attempt 1 of 1
[2025-09-06 13:02:17,228] {taskinstance.py:1358} INFO - 
--------------------------------------------------------------------------------
[2025-09-06 13:02:17,259] {taskinstance.py:1377} INFO - Executing <Task(PythonOperator): extrair_dados> on 2025-08-18 00:00:00+00:00
[2025-09-06 13:02:17,265] {standard_task_runner.py:52} INFO - Started process 36680 to run task
[2025-09-06 13:02:17,276] {standard_task_runner.py:79} INFO - Running: ['airflow', 'tasks', 'run', 'dados_climatico', 'extrair_dados', 'scheduled__2025-08-18T00:00:00+00:00', '--job-id', '37', '--raw', '--subdir', 'DAGS_FOLDER/dados_climaticos.py', '--cfg-path', '/tmp/tmpiow2e3pu', '--error-file', '/tmp/tmpqaas089h']
[2025-09-06 13:02:17,277] {standard_task_runner.py:80} INFO - Job 37: Subtask extrair_dados
[2025-09-06 13:02:17,362] {task_command.py:370} INFO - Running <TaskInstance: dados_climatico.extrair_dados scheduled__2025-08-18T00:00:00+00:00 [running]> on host lucas-Lenovo-ideapad-320-14IKB
[2025-09-06 13:02:17,463] {taskinstance.py:1569} INFO - Exporting the following env vars:
AIRFLOW_CTX_DAG_OWNER=airflow
AIRFLOW_CTX_DAG_ID=dados_climatico
AIRFLOW_CTX_TASK_ID=extrair_dados
AIRFLOW_CTX_EXECUTION_DATE=2025-08-18T00:00:00+00:00
AIRFLOW_CTX_TRY_NUMBER=1
AIRFLOW_CTX_DAG_RUN_ID=scheduled__2025-08-18T00:00:00+00:00
[2025-09-06 13:02:18,314] {python.py:173} INFO - Done. Returned value was: None
[2025-09-06 13:02:18,336] {taskinstance.py:1395} INFO - Marking task as SUCCESS. dag_id=dados_climatico, task_id=extrair_dados, execution_date=20250818T000000, start_date=20250906T160217, end_date=20250906T160218
[2025-09-06 13:02:18,414] {local_task_job.py:156} INFO - Task exited with return code 0
[2025-09-06 13:02:18,450] {local_task_job.py:273} INFO - 0 downstream tasks scheduled from follow-on schedule check
