[2025-09-06 12:51:42,998] {taskinstance.py:1159} INFO - Dependencies all met for <TaskInstance: dados_climatico.extrair_dados scheduled__2025-08-11T00:00:00+00:00 [queued]>
[2025-09-06 12:51:43,010] {taskinstance.py:1159} INFO - Dependencies all met for <TaskInstance: dados_climatico.extrair_dados scheduled__2025-08-11T00:00:00+00:00 [queued]>
[2025-09-06 12:51:43,010] {taskinstance.py:1356} INFO - 
--------------------------------------------------------------------------------
[2025-09-06 12:51:43,010] {taskinstance.py:1357} INFO - Starting attempt 1 of 1
[2025-09-06 12:51:43,010] {taskinstance.py:1358} INFO - 
--------------------------------------------------------------------------------
[2025-09-06 12:51:43,052] {taskinstance.py:1377} INFO - Executing <Task(PythonOperator): extrair_dados> on 2025-08-11 00:00:00+00:00
[2025-09-06 12:51:43,058] {standard_task_runner.py:52} INFO - Started process 35110 to run task
[2025-09-06 12:51:43,066] {standard_task_runner.py:79} INFO - Running: ['airflow', 'tasks', 'run', 'dados_climatico', 'extrair_dados', 'scheduled__2025-08-11T00:00:00+00:00', '--job-id', '27', '--raw', '--subdir', 'DAGS_FOLDER/dados_climaticos.py', '--cfg-path', '/tmp/tmpt7fug2nw', '--error-file', '/tmp/tmpg9o6lbds']
[2025-09-06 12:51:43,067] {standard_task_runner.py:80} INFO - Job 27: Subtask extrair_dados
[2025-09-06 12:51:43,154] {task_command.py:370} INFO - Running <TaskInstance: dados_climatico.extrair_dados scheduled__2025-08-11T00:00:00+00:00 [running]> on host lucas-Lenovo-ideapad-320-14IKB
[2025-09-06 12:51:43,250] {taskinstance.py:1569} INFO - Exporting the following env vars:
AIRFLOW_CTX_DAG_OWNER=airflow
AIRFLOW_CTX_DAG_ID=dados_climatico
AIRFLOW_CTX_TASK_ID=extrair_dados
AIRFLOW_CTX_EXECUTION_DATE=2025-08-11T00:00:00+00:00
AIRFLOW_CTX_TRY_NUMBER=1
AIRFLOW_CTX_DAG_RUN_ID=scheduled__2025-08-11T00:00:00+00:00
[2025-09-06 12:51:43,251] {taskinstance.py:1889} ERROR - Task failed with exception
Traceback (most recent call last):
  File "/home/lucas/Documents/airflowalura/venv/lib/python3.9/site-packages/airflow/operators/python.py", line 171, in execute
    return_value = self.execute_callable()
  File "/home/lucas/Documents/airflowalura/venv/lib/python3.9/site-packages/airflow/operators/python.py", line 189, in execute_callable
    return self.python_callable(*self.op_args, **self.op_kwargs)
  File "/home/lucas/Documents/airflowalura/dags/dados_climaticos.py", line 26, in extrair_dados
    data_fim = data_inicio.add(days= 7)
AttributeError: 'str' object has no attribute 'add'
[2025-09-06 12:51:43,259] {taskinstance.py:1395} INFO - Marking task as FAILED. dag_id=dados_climatico, task_id=extrair_dados, execution_date=20250811T000000, start_date=20250906T155142, end_date=20250906T155143
[2025-09-06 12:51:43,282] {standard_task_runner.py:92} ERROR - Failed to execute job 27 for task extrair_dados ('str' object has no attribute 'add'; 35110)
[2025-09-06 12:51:43,318] {local_task_job.py:156} INFO - Task exited with return code 1
[2025-09-06 12:51:43,346] {local_task_job.py:273} INFO - 0 downstream tasks scheduled from follow-on schedule check
[2025-09-06 13:02:09,214] {taskinstance.py:1159} INFO - Dependencies all met for <TaskInstance: dados_climatico.extrair_dados scheduled__2025-08-11T00:00:00+00:00 [queued]>
[2025-09-06 13:02:09,226] {taskinstance.py:1159} INFO - Dependencies all met for <TaskInstance: dados_climatico.extrair_dados scheduled__2025-08-11T00:00:00+00:00 [queued]>
[2025-09-06 13:02:09,226] {taskinstance.py:1356} INFO - 
--------------------------------------------------------------------------------
[2025-09-06 13:02:09,226] {taskinstance.py:1357} INFO - Starting attempt 1 of 1
[2025-09-06 13:02:09,226] {taskinstance.py:1358} INFO - 
--------------------------------------------------------------------------------
[2025-09-06 13:02:09,262] {taskinstance.py:1377} INFO - Executing <Task(PythonOperator): extrair_dados> on 2025-08-11 00:00:00+00:00
[2025-09-06 13:02:09,267] {standard_task_runner.py:52} INFO - Started process 36661 to run task
[2025-09-06 13:02:09,274] {standard_task_runner.py:79} INFO - Running: ['airflow', 'tasks', 'run', 'dados_climatico', 'extrair_dados', 'scheduled__2025-08-11T00:00:00+00:00', '--job-id', '35', '--raw', '--subdir', 'DAGS_FOLDER/dados_climaticos.py', '--cfg-path', '/tmp/tmp8lt7elby', '--error-file', '/tmp/tmpikjmg20t']
[2025-09-06 13:02:09,275] {standard_task_runner.py:80} INFO - Job 35: Subtask extrair_dados
[2025-09-06 13:02:09,378] {task_command.py:370} INFO - Running <TaskInstance: dados_climatico.extrair_dados scheduled__2025-08-11T00:00:00+00:00 [running]> on host lucas-Lenovo-ideapad-320-14IKB
[2025-09-06 13:02:09,480] {taskinstance.py:1569} INFO - Exporting the following env vars:
AIRFLOW_CTX_DAG_OWNER=airflow
AIRFLOW_CTX_DAG_ID=dados_climatico
AIRFLOW_CTX_TASK_ID=extrair_dados
AIRFLOW_CTX_EXECUTION_DATE=2025-08-11T00:00:00+00:00
AIRFLOW_CTX_TRY_NUMBER=1
AIRFLOW_CTX_DAG_RUN_ID=scheduled__2025-08-11T00:00:00+00:00
[2025-09-06 13:02:10,798] {python.py:173} INFO - Done. Returned value was: None
[2025-09-06 13:02:10,815] {taskinstance.py:1395} INFO - Marking task as SUCCESS. dag_id=dados_climatico, task_id=extrair_dados, execution_date=20250811T000000, start_date=20250906T160209, end_date=20250906T160210
[2025-09-06 13:02:10,894] {local_task_job.py:156} INFO - Task exited with return code 0
[2025-09-06 13:02:10,920] {local_task_job.py:273} INFO - 0 downstream tasks scheduled from follow-on schedule check
